Traceback (most recent call last):
  File "/opt/hostedtoolcache/Python/3.8.11/x64/lib/python3.8/site-packages/jupyter_cache/executors/utils.py", line 51, in single_nb_execution
    executenb(
  File "/opt/hostedtoolcache/Python/3.8.11/x64/lib/python3.8/site-packages/nbclient/client.py", line 1117, in execute
    return NotebookClient(nb=nb, resources=resources, km=km, **kwargs).execute()
  File "/opt/hostedtoolcache/Python/3.8.11/x64/lib/python3.8/site-packages/nbclient/util.py", line 78, in wrapped
    return just_run(coro(*args, **kwargs))
  File "/opt/hostedtoolcache/Python/3.8.11/x64/lib/python3.8/site-packages/nbclient/util.py", line 57, in just_run
    return loop.run_until_complete(coro)
  File "/opt/hostedtoolcache/Python/3.8.11/x64/lib/python3.8/asyncio/base_events.py", line 616, in run_until_complete
    return future.result()
  File "/opt/hostedtoolcache/Python/3.8.11/x64/lib/python3.8/site-packages/nbclient/client.py", line 558, in async_execute
    await self.async_execute_cell(
  File "/opt/hostedtoolcache/Python/3.8.11/x64/lib/python3.8/site-packages/nbclient/client.py", line 862, in async_execute_cell
    self._check_raise_for_error(cell, exec_reply)
  File "/opt/hostedtoolcache/Python/3.8.11/x64/lib/python3.8/site-packages/nbclient/client.py", line 765, in _check_raise_for_error
    raise CellExecutionError.from_cell_and_msg(cell, exec_reply_content)
nbclient.exceptions.CellExecutionError: An error occurred while executing the following cell:
------------------
from pandas import DataFrame as df

nclusters = range(2, 11)  # graspologic nclusters goes from 2 to max_clusters
silhouette = km_clust.silhouette_  # obtain the respective silhouette scores

silhouette_df = df({"Number of Clusters": nclusters, "Silhouette Score": silhouette})  # place into pandas dataframe

fig, ax = plt.subplots(1,1,figsize=(12, 6))

sns.lineplot(data=silhouette_df,ax=ax, x="Number of Clusters", y="Silhouette Score");
ax.set_title("Silhouette Analysis of KMeans Clusterings")
fig;
------------------

[0;31m---------------------------------------------------------------------------[0m
[0;31mNameError[0m                                 Traceback (most recent call last)
[0;32m/tmp/ipykernel_1871/1424549696.py[0m in [0;36m<module>[0;34m[0m
[1;32m      8[0m [0mfig[0m[0;34m,[0m [0max[0m [0;34m=[0m [0mplt[0m[0;34m.[0m[0msubplots[0m[0;34m([0m[0;36m1[0m[0;34m,[0m[0;36m1[0m[0;34m,[0m[0mfigsize[0m[0;34m=[0m[0;34m([0m[0;36m12[0m[0;34m,[0m [0;36m6[0m[0;34m)[0m[0;34m)[0m[0;34m[0m[0;34m[0m[0m
[1;32m      9[0m [0;34m[0m[0m
[0;32m---> 10[0;31m [0msns[0m[0;34m.[0m[0mlineplot[0m[0;34m([0m[0mdata[0m[0;34m=[0m[0msilhouette_df[0m[0;34m,[0m[0max[0m[0;34m=[0m[0max[0m[0;34m,[0m [0mx[0m[0;34m=[0m[0;34m"Number of Clusters"[0m[0;34m,[0m [0my[0m[0;34m=[0m[0;34m"Silhouette Score"[0m[0;34m)[0m[0;34m;[0m[0;34m[0m[0;34m[0m[0m
[0m[1;32m     11[0m [0max[0m[0;34m.[0m[0mset_title[0m[0;34m([0m[0;34m"Silhouette Analysis of KMeans Clusterings"[0m[0;34m)[0m[0;34m[0m[0;34m[0m[0m
[1;32m     12[0m [0mfig[0m[0;34m;[0m[0;34m[0m[0;34m[0m[0m

[0;31mNameError[0m: name 'sns' is not defined
NameError: name 'sns' is not defined

