Traceback (most recent call last):
  File "/opt/hostedtoolcache/Python/3.8.8/x64/lib/python3.8/site-packages/jupyter_cache/executors/utils.py", line 51, in single_nb_execution
    executenb(
  File "/opt/hostedtoolcache/Python/3.8.8/x64/lib/python3.8/site-packages/nbclient/client.py", line 1112, in execute
    return NotebookClient(nb=nb, resources=resources, km=km, **kwargs).execute()
  File "/opt/hostedtoolcache/Python/3.8.8/x64/lib/python3.8/site-packages/nbclient/util.py", line 74, in wrapped
    return just_run(coro(*args, **kwargs))
  File "/opt/hostedtoolcache/Python/3.8.8/x64/lib/python3.8/site-packages/nbclient/util.py", line 53, in just_run
    return loop.run_until_complete(coro)
  File "/opt/hostedtoolcache/Python/3.8.8/x64/lib/python3.8/asyncio/base_events.py", line 616, in run_until_complete
    return future.result()
  File "/opt/hostedtoolcache/Python/3.8.8/x64/lib/python3.8/site-packages/nbclient/client.py", line 553, in async_execute
    await self.async_execute_cell(
  File "/opt/hostedtoolcache/Python/3.8.8/x64/lib/python3.8/site-packages/nbclient/client.py", line 857, in async_execute_cell
    self._check_raise_for_error(cell, exec_reply)
  File "/opt/hostedtoolcache/Python/3.8.8/x64/lib/python3.8/site-packages/nbclient/client.py", line 760, in _check_raise_for_error
    raise CellExecutionError.from_cell_and_msg(cell, exec_reply_content)
nbclient.exceptions.CellExecutionError: An error occurred while executing the following cell:
------------------
import graspologic

casc = graspologic.embed.CovariateAssistedEmbedding(embedding_alg="assortative", n_components=2, tuning_runs=10)
latents = casc.fit_transform(A, covariates=X)
plot_latents(latents, title="Embedding our model using graspologic", labels=labels);
------------------

[0;31m---------------------------------------------------------------------------[0m
[0;31mTypeError[0m                                 Traceback (most recent call last)
[0;32m<ipython-input-17-87e477c82097>[0m in [0;36m<module>[0;34m[0m
[1;32m      1[0m [0;32mimport[0m [0mgraspologic[0m[0;34m[0m[0;34m[0m[0m
[1;32m      2[0m [0;34m[0m[0m
[0;32m----> 3[0;31m [0mcasc[0m [0;34m=[0m [0mgraspologic[0m[0;34m.[0m[0membed[0m[0;34m.[0m[0mCovariateAssistedEmbedding[0m[0;34m([0m[0membedding_alg[0m[0;34m=[0m[0;34m"assortative"[0m[0;34m,[0m [0mn_components[0m[0;34m=[0m[0;36m2[0m[0;34m,[0m [0mtuning_runs[0m[0;34m=[0m[0;36m10[0m[0;34m)[0m[0;34m[0m[0;34m[0m[0m
[0m[1;32m      4[0m [0mlatents[0m [0;34m=[0m [0mcasc[0m[0;34m.[0m[0mfit_transform[0m[0;34m([0m[0mA[0m[0;34m,[0m [0mcovariates[0m[0;34m=[0m[0mX[0m[0;34m)[0m[0;34m[0m[0;34m[0m[0m
[1;32m      5[0m [0mplot_latents[0m[0;34m([0m[0mlatents[0m[0;34m,[0m [0mtitle[0m[0;34m=[0m[0;34m"Embedding our model using graspologic"[0m[0;34m,[0m [0mlabels[0m[0;34m=[0m[0mlabels[0m[0;34m)[0m[0;34m;[0m[0;34m[0m[0;34m[0m[0m

[0;31mTypeError[0m: __init__() got an unexpected keyword argument 'tuning_runs'
TypeError: __init__() got an unexpected keyword argument 'tuning_runs'

