Traceback (most recent call last):
  File "/opt/hostedtoolcache/Python/3.8.8/x64/lib/python3.8/site-packages/jupyter_cache/executors/utils.py", line 51, in single_nb_execution
    executenb(
  File "/opt/hostedtoolcache/Python/3.8.8/x64/lib/python3.8/site-packages/nbclient/client.py", line 1112, in execute
    return NotebookClient(nb=nb, resources=resources, km=km, **kwargs).execute()
  File "/opt/hostedtoolcache/Python/3.8.8/x64/lib/python3.8/site-packages/nbclient/util.py", line 74, in wrapped
    return just_run(coro(*args, **kwargs))
  File "/opt/hostedtoolcache/Python/3.8.8/x64/lib/python3.8/site-packages/nbclient/util.py", line 53, in just_run
    return loop.run_until_complete(coro)
  File "/opt/hostedtoolcache/Python/3.8.8/x64/lib/python3.8/asyncio/base_events.py", line 616, in run_until_complete
    return future.result()
  File "/opt/hostedtoolcache/Python/3.8.8/x64/lib/python3.8/site-packages/nbclient/client.py", line 553, in async_execute
    await self.async_execute_cell(
  File "/opt/hostedtoolcache/Python/3.8.8/x64/lib/python3.8/site-packages/nbclient/client.py", line 857, in async_execute_cell
    self._check_raise_for_error(cell, exec_reply)
  File "/opt/hostedtoolcache/Python/3.8.8/x64/lib/python3.8/site-packages/nbclient/client.py", line 760, in _check_raise_for_error
    raise CellExecutionError.from_cell_and_msg(cell, exec_reply_content)
nbclient.exceptions.CellExecutionError: An error occurred while executing the following cell:
------------------
from graspologic.embed import LaplacianSpectralEmbed as LSE


# Plot
fig, axs = plt.subplots(1, 3, figsize=(15,5))
plot_latents(L_latents, title="Latent positions when we only use the Laplacian", 
             labels=labels, ax=axs[0])
plot_latents(X_latents, title="Latent positions when we only use our covariates", 
             labels=labels, ax=axs[1]);
plot_latents(latents_, title="Latent positions when we combine\n our network and its covariates", 
             labels=labels, ax=axs[2])

plt.tight_layout()
------------------

[0;31m---------------------------------------------------------------------------[0m
[0;31mNameError[0m                                 Traceback (most recent call last)
[0;32m<ipython-input-10-5d6ab5827772>[0m in [0;36m<module>[0;34m[0m
[1;32m      8[0m plot_latents(X_latents, title="Latent positions when we only use our covariates", 
[1;32m      9[0m              labels=labels, ax=axs[1]);
[0;32m---> 10[0;31m plot_latents(latents_, title="Latent positions when we combine\n our network and its covariates", 
[0m[1;32m     11[0m              labels=labels, ax=axs[2])
[1;32m     12[0m [0;34m[0m[0m

[0;31mNameError[0m: name 'latents_' is not defined
NameError: name 'latents_' is not defined

