Traceback (most recent call last):
  File "/opt/hostedtoolcache/Python/3.8.8/x64/lib/python3.8/site-packages/jupyter_cache/executors/utils.py", line 51, in single_nb_execution
    executenb(
  File "/opt/hostedtoolcache/Python/3.8.8/x64/lib/python3.8/site-packages/nbclient/client.py", line 1112, in execute
    return NotebookClient(nb=nb, resources=resources, km=km, **kwargs).execute()
  File "/opt/hostedtoolcache/Python/3.8.8/x64/lib/python3.8/site-packages/nbclient/util.py", line 74, in wrapped
    return just_run(coro(*args, **kwargs))
  File "/opt/hostedtoolcache/Python/3.8.8/x64/lib/python3.8/site-packages/nbclient/util.py", line 53, in just_run
    return loop.run_until_complete(coro)
  File "/opt/hostedtoolcache/Python/3.8.8/x64/lib/python3.8/asyncio/base_events.py", line 616, in run_until_complete
    return future.result()
  File "/opt/hostedtoolcache/Python/3.8.8/x64/lib/python3.8/site-packages/nbclient/client.py", line 553, in async_execute
    await self.async_execute_cell(
  File "/opt/hostedtoolcache/Python/3.8.8/x64/lib/python3.8/site-packages/nbclient/client.py", line 857, in async_execute_cell
    self._check_raise_for_error(cell, exec_reply)
  File "/opt/hostedtoolcache/Python/3.8.8/x64/lib/python3.8/site-packages/nbclient/client.py", line 760, in _check_raise_for_error
    raise CellExecutionError.from_cell_and_msg(cell, exec_reply_content)
nbclient.exceptions.CellExecutionError: An error occurred while executing the following cell:
------------------
from matlotlib.gridspec import GridSpec

# generate grid spec
fig = plt.figure(tight_layout=True, figsize=(10, 6.5))
# fig, axs = plt.subplots(nrows=1, ncols=2, figsize=(10, 5))
heatmap(L_, title=f"Our Combined Laplacian and \ncovariates matrix with a weight of {weight:.2f}", ax=axs[0])
plot_latents(latents_, 
             title=f"Embedding of the combined matrix", 
             labels=labels, ax=axs[1]);

plt.tight_layout()
------------------

[0;31m---------------------------------------------------------------------------[0m
[0;31mModuleNotFoundError[0m                       Traceback (most recent call last)
[0;32m<ipython-input-15-9a54e7bb97d1>[0m in [0;36m<module>[0;34m[0m
[0;32m----> 1[0;31m [0;32mfrom[0m [0mmatlotlib[0m[0;34m.[0m[0mgridspec[0m [0;32mimport[0m [0mGridSpec[0m[0;34m[0m[0;34m[0m[0m
[0m[1;32m      2[0m [0;34m[0m[0m
[1;32m      3[0m [0;31m# generate grid spec[0m[0;34m[0m[0;34m[0m[0;34m[0m[0m
[1;32m      4[0m [0mfig[0m [0;34m=[0m [0mplt[0m[0;34m.[0m[0mfigure[0m[0;34m([0m[0mtight_layout[0m[0;34m=[0m[0;32mTrue[0m[0;34m,[0m [0mfigsize[0m[0;34m=[0m[0;34m([0m[0;36m10[0m[0;34m,[0m [0;36m6.5[0m[0;34m)[0m[0;34m)[0m[0;34m[0m[0;34m[0m[0m
[1;32m      5[0m [0;31m# fig, axs = plt.subplots(nrows=1, ncols=2, figsize=(10, 5))[0m[0;34m[0m[0;34m[0m[0;34m[0m[0m

[0;31mModuleNotFoundError[0m: No module named 'matlotlib'
ModuleNotFoundError: No module named 'matlotlib'

