Traceback (most recent call last):
  File "/opt/hostedtoolcache/Python/3.8.9/x64/lib/python3.8/site-packages/jupyter_cache/executors/utils.py", line 51, in single_nb_execution
    executenb(
  File "/opt/hostedtoolcache/Python/3.8.9/x64/lib/python3.8/site-packages/nbclient/client.py", line 1112, in execute
    return NotebookClient(nb=nb, resources=resources, km=km, **kwargs).execute()
  File "/opt/hostedtoolcache/Python/3.8.9/x64/lib/python3.8/site-packages/nbclient/util.py", line 74, in wrapped
    return just_run(coro(*args, **kwargs))
  File "/opt/hostedtoolcache/Python/3.8.9/x64/lib/python3.8/site-packages/nbclient/util.py", line 53, in just_run
    return loop.run_until_complete(coro)
  File "/opt/hostedtoolcache/Python/3.8.9/x64/lib/python3.8/asyncio/base_events.py", line 616, in run_until_complete
    return future.result()
  File "/opt/hostedtoolcache/Python/3.8.9/x64/lib/python3.8/site-packages/nbclient/client.py", line 553, in async_execute
    await self.async_execute_cell(
  File "/opt/hostedtoolcache/Python/3.8.9/x64/lib/python3.8/site-packages/nbclient/client.py", line 857, in async_execute_cell
    self._check_raise_for_error(cell, exec_reply)
  File "/opt/hostedtoolcache/Python/3.8.9/x64/lib/python3.8/site-packages/nbclient/client.py", line 760, in _check_raise_for_error
    raise CellExecutionError.from_cell_and_msg(cell, exec_reply_content)
nbclient.exceptions.CellExecutionError: An error occurred while executing the following cell:
------------------
import numpy as np
from graspologic.simulations import sbm

n = 100
p1, p2, p3 = .12, .06, .03
A1, labels = make_network(p1, p3, p3, p1, 
                      return_labels=True)
A2 = make_network(p1, p3, p3, p2)
A3 = make_network(p3, p2, p2, p3)
A4 = make_network(p1, p3, p3, p3)
------------------

[0;31m---------------------------------------------------------------------------[0m
[0;31mTypeError[0m                                 Traceback (most recent call last)
[0;32m<ipython-input-15-5eeef267f4e7>[0m in [0;36m<module>[0;34m[0m
[1;32m      4[0m [0mn[0m [0;34m=[0m [0;36m100[0m[0;34m[0m[0;34m[0m[0m
[1;32m      5[0m [0mp1[0m[0;34m,[0m [0mp2[0m[0;34m,[0m [0mp3[0m [0;34m=[0m [0;36m.12[0m[0;34m,[0m [0;36m.06[0m[0;34m,[0m [0;36m.03[0m[0;34m[0m[0;34m[0m[0m
[0;32m----> 6[0;31m A1, labels = make_network(p1, p3, p3, p1, 
[0m[1;32m      7[0m                       return_labels=True)
[1;32m      8[0m [0mA2[0m [0;34m=[0m [0mmake_network[0m[0;34m([0m[0mp1[0m[0;34m,[0m [0mp3[0m[0;34m,[0m [0mp3[0m[0;34m,[0m [0mp2[0m[0;34m)[0m[0;34m[0m[0;34m[0m[0m

[0;31mTypeError[0m: make_network() got an unexpected keyword argument 'return_labels'
TypeError: make_network() got an unexpected keyword argument 'return_labels'

