Traceback (most recent call last):
  File "/opt/hostedtoolcache/Python/3.8.8/x64/lib/python3.8/site-packages/jupyter_cache/executors/utils.py", line 51, in single_nb_execution
    executenb(
  File "/opt/hostedtoolcache/Python/3.8.8/x64/lib/python3.8/site-packages/nbclient/client.py", line 1112, in execute
    return NotebookClient(nb=nb, resources=resources, km=km, **kwargs).execute()
  File "/opt/hostedtoolcache/Python/3.8.8/x64/lib/python3.8/site-packages/nbclient/util.py", line 74, in wrapped
    return just_run(coro(*args, **kwargs))
  File "/opt/hostedtoolcache/Python/3.8.8/x64/lib/python3.8/site-packages/nbclient/util.py", line 53, in just_run
    return loop.run_until_complete(coro)
  File "/opt/hostedtoolcache/Python/3.8.8/x64/lib/python3.8/asyncio/base_events.py", line 616, in run_until_complete
    return future.result()
  File "/opt/hostedtoolcache/Python/3.8.8/x64/lib/python3.8/site-packages/nbclient/client.py", line 553, in async_execute
    await self.async_execute_cell(
  File "/opt/hostedtoolcache/Python/3.8.8/x64/lib/python3.8/site-packages/nbclient/client.py", line 857, in async_execute_cell
    self._check_raise_for_error(cell, exec_reply)
  File "/opt/hostedtoolcache/Python/3.8.8/x64/lib/python3.8/site-packages/nbclient/client.py", line 760, in _check_raise_for_error
    raise CellExecutionError.from_cell_and_msg(cell, exec_reply_content)
nbclient.exceptions.CellExecutionError: An error occurred while executing the following cell:
------------------
from graspologic.plot import binary_heatmap
import matplotlib.pyplot as plt
from matplotlib.colors import ListedColormap


fig, axs = plt.subplots(2, 2, figsize=(5,5))
for ax, graph in zip(axs.flat, [A1, A2, A3, A4]):
    hmap = binary_heatmap(graph, ax=ax, cbar=False)
    for spine in ax.spines.values():
        spine.set_visible(True)
    hmap.vlines(n, 0, n*2, colors="black", lw=.9, linestyle="dashed", alpha=.8)
    hmap.hlines(n, 0, n*2, colors="black", lw=.9, linestyle="dashed", alpha=.8)
    
plt.suptitle("Four different networks", fontsize=18)
fig.subplots_adjust(hspace=.05, wspace=.05)

cmap = ListedColormap(["white", "black"])
cbar_ax = fig.add_axes([.95, 0.13, 0.07, 0.75])
cbar = fig.colorbar(hmap.imshow(A1, cmap=cmap), cax=cbar_ax)
cbar.set_ticks([0.25, 0.75])
cbar.set_ticklabels(["No Edge", "Edge"])
------------------

[0;31m---------------------------------------------------------------------------[0m
[0;31mImportError[0m                               Traceback (most recent call last)
[0;32m<ipython-input-2-c6eb9ad31271>[0m in [0;36m<module>[0;34m[0m
[0;32m----> 1[0;31m [0;32mfrom[0m [0mgraspologic[0m[0;34m.[0m[0mplot[0m [0;32mimport[0m [0mbinary_heatmap[0m[0;34m[0m[0;34m[0m[0m
[0m[1;32m      2[0m [0;32mimport[0m [0mmatplotlib[0m[0;34m.[0m[0mpyplot[0m [0;32mas[0m [0mplt[0m[0;34m[0m[0;34m[0m[0m
[1;32m      3[0m [0;32mfrom[0m [0mmatplotlib[0m[0;34m.[0m[0mcolors[0m [0;32mimport[0m [0mListedColormap[0m[0;34m[0m[0;34m[0m[0m
[1;32m      4[0m [0;34m[0m[0m
[1;32m      5[0m [0;34m[0m[0m

[0;31mImportError[0m: cannot import name 'binary_heatmap' from 'graspologic.plot' (/opt/hostedtoolcache/Python/3.8.8/x64/lib/python3.8/site-packages/graspologic/plot/__init__.py)
ImportError: cannot import name 'binary_heatmap' from 'graspologic.plot' (/opt/hostedtoolcache/Python/3.8.8/x64/lib/python3.8/site-packages/graspologic/plot/__init__.py)

