Traceback (most recent call last):
  File "/opt/hostedtoolcache/Python/3.8.9/x64/lib/python3.8/site-packages/jupyter_cache/executors/utils.py", line 51, in single_nb_execution
    executenb(
  File "/opt/hostedtoolcache/Python/3.8.9/x64/lib/python3.8/site-packages/nbclient/client.py", line 1112, in execute
    return NotebookClient(nb=nb, resources=resources, km=km, **kwargs).execute()
  File "/opt/hostedtoolcache/Python/3.8.9/x64/lib/python3.8/site-packages/nbclient/util.py", line 74, in wrapped
    return just_run(coro(*args, **kwargs))
  File "/opt/hostedtoolcache/Python/3.8.9/x64/lib/python3.8/site-packages/nbclient/util.py", line 53, in just_run
    return loop.run_until_complete(coro)
  File "/opt/hostedtoolcache/Python/3.8.9/x64/lib/python3.8/asyncio/base_events.py", line 616, in run_until_complete
    return future.result()
  File "/opt/hostedtoolcache/Python/3.8.9/x64/lib/python3.8/site-packages/nbclient/client.py", line 553, in async_execute
    await self.async_execute_cell(
  File "/opt/hostedtoolcache/Python/3.8.9/x64/lib/python3.8/site-packages/nbclient/client.py", line 857, in async_execute_cell
    self._check_raise_for_error(cell, exec_reply)
  File "/opt/hostedtoolcache/Python/3.8.9/x64/lib/python3.8/site-packages/nbclient/client.py", line 760, in _check_raise_for_error
    raise CellExecutionError.from_cell_and_msg(cell, exec_reply_content)
nbclient.exceptions.CellExecutionError: An error occurred while executing the following cell:
------------------
fig, axs = plt.subplots(2, 2, figsize=(7,7), sharex=True, sharey=True)
for i, ax in enumerate(axs.flat):
    plot_latents(latents[i], title=f"Embedding for network {i+1}", 
                 labels=labels, ax=ax, legend=False)
    ax.yaxis.set_major_locator(plt.MaxNLocator(3))
plt.suptitle("Embeddings of our four networks", fontsize=20);

h, l = ax.get_legend_handles_labels()
fig.legend(h, l, loc='center right', bbox_to_anchor=(1.25, .5), 
           prop={'size': 15}, title="Community", title_fontsize='x-large');

fig.supxlabel("Dimension 1")
fig.supylabel("Dimension 2");

plt.tight_layout()
------------------

[0;31m---------------------------------------------------------------------------[0m
[0;31mAttributeError[0m                            Traceback (most recent call last)
[0;32m<ipython-input-20-9a5c1e2981a3>[0m in [0;36m<module>[0;34m[0m
[1;32m     10[0m            prop={'size': 15}, title="Community", title_fontsize='x-large');
[1;32m     11[0m [0;34m[0m[0m
[0;32m---> 12[0;31m [0mfig[0m[0;34m.[0m[0msupxlabel[0m[0;34m([0m[0;34m"Dimension 1"[0m[0;34m)[0m[0;34m[0m[0;34m[0m[0m
[0m[1;32m     13[0m [0mfig[0m[0;34m.[0m[0msupylabel[0m[0;34m([0m[0;34m"Dimension 2"[0m[0;34m)[0m[0;34m;[0m[0;34m[0m[0;34m[0m[0m
[1;32m     14[0m [0;34m[0m[0m

[0;31mAttributeError[0m: 'Figure' object has no attribute 'supxlabel'
AttributeError: 'Figure' object has no attribute 'supxlabel'

